INFO:root:BOT starting... Date: Mon Mar  7 15:59:57 2022
INFO:apscheduler.scheduler:Scheduler started
WARNING:telegram.vendor.ptb_urllib3.urllib3.connectionpool:Retrying (Retry(total=2, connect=None, read=None, redirect=None)) after connection broken by 'ConnectTimeoutError(<telegram.vendor.ptb_urllib3.urllib3.contrib.socks.SOCKSHTTPSConnection object at 0x7f98b9e2f6d0>, 'Connection to api.telegram.org timed out. (connect timeout=5.0)')': /bot5196914876:AAHeANqoy4sOKsF04EjsZZhxQGruBIDKeks/getMe
WARNING:telegram.vendor.ptb_urllib3.urllib3.connectionpool:Retrying (Retry(total=1, connect=None, read=None, redirect=None)) after connection broken by 'ConnectTimeoutError(<telegram.vendor.ptb_urllib3.urllib3.contrib.socks.SOCKSHTTPSConnection object at 0x7f98b9e2f9d0>, 'Connection to api.telegram.org timed out. (connect timeout=5.0)')': /bot5196914876:AAHeANqoy4sOKsF04EjsZZhxQGruBIDKeks/getMe
WARNING:telegram.vendor.ptb_urllib3.urllib3.connectionpool:Retrying (Retry(total=0, connect=None, read=None, redirect=None)) after connection broken by 'ConnectTimeoutError(<telegram.vendor.ptb_urllib3.urllib3.contrib.socks.SOCKSHTTPSConnection object at 0x7f98b9e2fb80>, 'Connection to api.telegram.org timed out. (connect timeout=5.0)')': /bot5196914876:AAHeANqoy4sOKsF04EjsZZhxQGruBIDKeks/getMe
INFO:root:BOT starting... Date: Mon Mar  7 16:02:10 2022
INFO:apscheduler.scheduler:Scheduler started
ERROR:telegram.ext.dispatcher:No error handlers are registered, logging exception.
Traceback (most recent call last):
  File "/Library/Frameworks/Python.framework/Versions/3.9/lib/python3.9/site-packages/telegram/vendor/ptb_urllib3/urllib3/connectionpool.py", line 402, in _make_request
    six.raise_from(e, None)
  File "<string>", line 2, in raise_from
  File "/Library/Frameworks/Python.framework/Versions/3.9/lib/python3.9/site-packages/telegram/vendor/ptb_urllib3/urllib3/connectionpool.py", line 398, in _make_request
    httplib_response = conn.getresponse()
  File "/Library/Frameworks/Python.framework/Versions/3.9/lib/python3.9/http/client.py", line 1347, in getresponse
    response.begin()
  File "/Library/Frameworks/Python.framework/Versions/3.9/lib/python3.9/http/client.py", line 307, in begin
    version, status, reason = self._read_status()
  File "/Library/Frameworks/Python.framework/Versions/3.9/lib/python3.9/http/client.py", line 268, in _read_status
    line = str(self.fp.readline(_MAXLINE + 1), "iso-8859-1")
  File "/Library/Frameworks/Python.framework/Versions/3.9/lib/python3.9/socket.py", line 704, in readinto
    return self._sock.recv_into(b)
  File "/Library/Frameworks/Python.framework/Versions/3.9/lib/python3.9/ssl.py", line 1241, in recv_into
    return self.read(nbytes, buffer)
  File "/Library/Frameworks/Python.framework/Versions/3.9/lib/python3.9/ssl.py", line 1099, in read
    return self._sslobj.read(len, buffer)
socket.timeout: The read operation timed out

During handling of the above exception, another exception occurred:

Traceback (most recent call last):
  File "/Library/Frameworks/Python.framework/Versions/3.9/lib/python3.9/site-packages/telegram/utils/request.py", line 259, in _request_wrapper
    resp = self._con_pool.request(*args, **kwargs)
  File "/Library/Frameworks/Python.framework/Versions/3.9/lib/python3.9/site-packages/telegram/vendor/ptb_urllib3/urllib3/request.py", line 68, in request
    return self.request_encode_body(method, url, fields=fields,
  File "/Library/Frameworks/Python.framework/Versions/3.9/lib/python3.9/site-packages/telegram/vendor/ptb_urllib3/urllib3/request.py", line 148, in request_encode_body
    return self.urlopen(method, url, **extra_kw)
  File "/Library/Frameworks/Python.framework/Versions/3.9/lib/python3.9/site-packages/telegram/vendor/ptb_urllib3/urllib3/poolmanager.py", line 244, in urlopen
    response = conn.urlopen(method, u.request_uri, **kw)
  File "/Library/Frameworks/Python.framework/Versions/3.9/lib/python3.9/site-packages/telegram/vendor/ptb_urllib3/urllib3/connectionpool.py", line 665, in urlopen
    retries = retries.increment(method, url, error=e, _pool=self,
  File "/Library/Frameworks/Python.framework/Versions/3.9/lib/python3.9/site-packages/telegram/vendor/ptb_urllib3/urllib3/util/retry.py", line 347, in increment
    raise six.reraise(type(error), error, _stacktrace)
  File "/Library/Frameworks/Python.framework/Versions/3.9/lib/python3.9/site-packages/telegram/vendor/ptb_urllib3/urllib3/packages/six.py", line 686, in reraise
    raise value
  File "/Library/Frameworks/Python.framework/Versions/3.9/lib/python3.9/site-packages/telegram/vendor/ptb_urllib3/urllib3/connectionpool.py", line 614, in urlopen
    httplib_response = self._make_request(conn, method, url,
  File "/Library/Frameworks/Python.framework/Versions/3.9/lib/python3.9/site-packages/telegram/vendor/ptb_urllib3/urllib3/connectionpool.py", line 404, in _make_request
    self._raise_timeout(err=e, url=url, timeout_value=read_timeout,
  File "/Library/Frameworks/Python.framework/Versions/3.9/lib/python3.9/site-packages/telegram/vendor/ptb_urllib3/urllib3/connectionpool.py", line 321, in _raise_timeout
    raise exc_cls(*args)
telegram.vendor.ptb_urllib3.urllib3.exceptions.ReadTimeoutError: HTTPSConnectionPool(host='api.telegram.org', port=443): Read timed out. (read timeout=5.0)

The above exception was the direct cause of the following exception:

Traceback (most recent call last):
  File "/Library/Frameworks/Python.framework/Versions/3.9/lib/python3.9/site-packages/telegram/ext/dispatcher.py", line 555, in process_update
    handler.handle_update(update, self, check, context)
  File "/Library/Frameworks/Python.framework/Versions/3.9/lib/python3.9/site-packages/telegram/ext/handler.py", line 198, in handle_update
    return self.callback(update, context)
  File "/Users/anastasiyasundeeva/learnpython/mybot/handlers.py", line 6, in info_view
    update.message.reply_text(f'{info_bots}',reply_markup=main_keyboard())
  File "/Library/Frameworks/Python.framework/Versions/3.9/lib/python3.9/site-packages/telegram/message.py", line 791, in reply_text
    return self.bot.send_message(
  File "/Library/Frameworks/Python.framework/Versions/3.9/lib/python3.9/site-packages/telegram/bot.py", line 130, in decorator
    result = func(*args, **kwargs)
  File "/Library/Frameworks/Python.framework/Versions/3.9/lib/python3.9/site-packages/telegram/bot.py", line 522, in send_message
    return self._message(  # type: ignore[return-value]
  File "/Library/Frameworks/Python.framework/Versions/3.9/lib/python3.9/site-packages/telegram/ext/extbot.py", line 200, in _message
    result = super()._message(
  File "/Library/Frameworks/Python.framework/Versions/3.9/lib/python3.9/site-packages/telegram/bot.py", line 336, in _message
    result = self._post(endpoint, data, timeout=timeout, api_kwargs=api_kwargs)
  File "/Library/Frameworks/Python.framework/Versions/3.9/lib/python3.9/site-packages/telegram/bot.py", line 295, in _post
    return self.request.post(
  File "/Library/Frameworks/Python.framework/Versions/3.9/lib/python3.9/site-packages/telegram/utils/request.py", line 361, in post
    result = self._request_wrapper(
  File "/Library/Frameworks/Python.framework/Versions/3.9/lib/python3.9/site-packages/telegram/utils/request.py", line 261, in _request_wrapper
    raise TimedOut() from error
telegram.error.TimedOut: Timed out
ERROR:telegram.ext.dispatcher:No error handlers are registered, logging exception.
Traceback (most recent call last):
  File "/Library/Frameworks/Python.framework/Versions/3.9/lib/python3.9/site-packages/telegram/vendor/ptb_urllib3/urllib3/connectionpool.py", line 402, in _make_request
    six.raise_from(e, None)
  File "<string>", line 2, in raise_from
  File "/Library/Frameworks/Python.framework/Versions/3.9/lib/python3.9/site-packages/telegram/vendor/ptb_urllib3/urllib3/connectionpool.py", line 398, in _make_request
    httplib_response = conn.getresponse()
  File "/Library/Frameworks/Python.framework/Versions/3.9/lib/python3.9/http/client.py", line 1347, in getresponse
    response.begin()
  File "/Library/Frameworks/Python.framework/Versions/3.9/lib/python3.9/http/client.py", line 307, in begin
    version, status, reason = self._read_status()
  File "/Library/Frameworks/Python.framework/Versions/3.9/lib/python3.9/http/client.py", line 268, in _read_status
    line = str(self.fp.readline(_MAXLINE + 1), "iso-8859-1")
  File "/Library/Frameworks/Python.framework/Versions/3.9/lib/python3.9/socket.py", line 704, in readinto
    return self._sock.recv_into(b)
  File "/Library/Frameworks/Python.framework/Versions/3.9/lib/python3.9/ssl.py", line 1241, in recv_into
    return self.read(nbytes, buffer)
  File "/Library/Frameworks/Python.framework/Versions/3.9/lib/python3.9/ssl.py", line 1099, in read
    return self._sslobj.read(len, buffer)
socket.timeout: The read operation timed out

During handling of the above exception, another exception occurred:

Traceback (most recent call last):
  File "/Library/Frameworks/Python.framework/Versions/3.9/lib/python3.9/site-packages/telegram/utils/request.py", line 259, in _request_wrapper
    resp = self._con_pool.request(*args, **kwargs)
  File "/Library/Frameworks/Python.framework/Versions/3.9/lib/python3.9/site-packages/telegram/vendor/ptb_urllib3/urllib3/request.py", line 68, in request
    return self.request_encode_body(method, url, fields=fields,
  File "/Library/Frameworks/Python.framework/Versions/3.9/lib/python3.9/site-packages/telegram/vendor/ptb_urllib3/urllib3/request.py", line 148, in request_encode_body
    return self.urlopen(method, url, **extra_kw)
  File "/Library/Frameworks/Python.framework/Versions/3.9/lib/python3.9/site-packages/telegram/vendor/ptb_urllib3/urllib3/poolmanager.py", line 244, in urlopen
    response = conn.urlopen(method, u.request_uri, **kw)
  File "/Library/Frameworks/Python.framework/Versions/3.9/lib/python3.9/site-packages/telegram/vendor/ptb_urllib3/urllib3/connectionpool.py", line 665, in urlopen
    retries = retries.increment(method, url, error=e, _pool=self,
  File "/Library/Frameworks/Python.framework/Versions/3.9/lib/python3.9/site-packages/telegram/vendor/ptb_urllib3/urllib3/util/retry.py", line 347, in increment
    raise six.reraise(type(error), error, _stacktrace)
  File "/Library/Frameworks/Python.framework/Versions/3.9/lib/python3.9/site-packages/telegram/vendor/ptb_urllib3/urllib3/packages/six.py", line 686, in reraise
    raise value
  File "/Library/Frameworks/Python.framework/Versions/3.9/lib/python3.9/site-packages/telegram/vendor/ptb_urllib3/urllib3/connectionpool.py", line 614, in urlopen
    httplib_response = self._make_request(conn, method, url,
  File "/Library/Frameworks/Python.framework/Versions/3.9/lib/python3.9/site-packages/telegram/vendor/ptb_urllib3/urllib3/connectionpool.py", line 404, in _make_request
    self._raise_timeout(err=e, url=url, timeout_value=read_timeout,
  File "/Library/Frameworks/Python.framework/Versions/3.9/lib/python3.9/site-packages/telegram/vendor/ptb_urllib3/urllib3/connectionpool.py", line 321, in _raise_timeout
    raise exc_cls(*args)
telegram.vendor.ptb_urllib3.urllib3.exceptions.ReadTimeoutError: HTTPSConnectionPool(host='api.telegram.org', port=443): Read timed out. (read timeout=5.0)

The above exception was the direct cause of the following exception:

Traceback (most recent call last):
  File "/Library/Frameworks/Python.framework/Versions/3.9/lib/python3.9/site-packages/telegram/ext/dispatcher.py", line 555, in process_update
    handler.handle_update(update, self, check, context)
  File "/Library/Frameworks/Python.framework/Versions/3.9/lib/python3.9/site-packages/telegram/ext/handler.py", line 198, in handle_update
    return self.callback(update, context)
  File "/Users/anastasiyasundeeva/learnpython/mybot/handlers.py", line 11, in talk_bot
    update.message.reply_text(f'{text}',reply_markup=main_keyboard())
  File "/Library/Frameworks/Python.framework/Versions/3.9/lib/python3.9/site-packages/telegram/message.py", line 791, in reply_text
    return self.bot.send_message(
  File "/Library/Frameworks/Python.framework/Versions/3.9/lib/python3.9/site-packages/telegram/bot.py", line 130, in decorator
    result = func(*args, **kwargs)
  File "/Library/Frameworks/Python.framework/Versions/3.9/lib/python3.9/site-packages/telegram/bot.py", line 522, in send_message
    return self._message(  # type: ignore[return-value]
  File "/Library/Frameworks/Python.framework/Versions/3.9/lib/python3.9/site-packages/telegram/ext/extbot.py", line 200, in _message
    result = super()._message(
  File "/Library/Frameworks/Python.framework/Versions/3.9/lib/python3.9/site-packages/telegram/bot.py", line 336, in _message
    result = self._post(endpoint, data, timeout=timeout, api_kwargs=api_kwargs)
  File "/Library/Frameworks/Python.framework/Versions/3.9/lib/python3.9/site-packages/telegram/bot.py", line 295, in _post
    return self.request.post(
  File "/Library/Frameworks/Python.framework/Versions/3.9/lib/python3.9/site-packages/telegram/utils/request.py", line 361, in post
    result = self._request_wrapper(
  File "/Library/Frameworks/Python.framework/Versions/3.9/lib/python3.9/site-packages/telegram/utils/request.py", line 261, in _request_wrapper
    raise TimedOut() from error
telegram.error.TimedOut: Timed out
INFO:telegram.ext.updater:Received signal 2 (SIGINT), stopping...
INFO:apscheduler.scheduler:Scheduler has been shut down
WARNING:telegram.ext.updater:Exiting immediately!
INFO:root:BOT starting... Date: Mon Mar  7 17:08:57 2022
INFO:apscheduler.scheduler:Scheduler started
INFO:telegram.ext.updater:Received signal 2 (SIGINT), stopping...
INFO:apscheduler.scheduler:Scheduler has been shut down
WARNING:telegram.ext.updater:Exiting immediately!
INFO:root:BOT starting... Date: Mon Mar  7 17:14:12 2022
INFO:apscheduler.scheduler:Scheduler started
ERROR:telegram.ext.dispatcher:No error handlers are registered, logging exception.
Traceback (most recent call last):
  File "/Library/Frameworks/Python.framework/Versions/3.9/lib/python3.9/site-packages/telegram/ext/dispatcher.py", line 555, in process_update
    handler.handle_update(update, self, check, context)
  File "/Library/Frameworks/Python.framework/Versions/3.9/lib/python3.9/site-packages/telegram/ext/handler.py", line 198, in handle_update
    return self.callback(update, context)
  File "/Users/anastasiyasundeeva/learnpython/mybot/handlers.py", line 38, in vacansies_list
    update.message.reply_text(f'{text}',reply_markup= vacansies_keyboard())
  File "/Library/Frameworks/Python.framework/Versions/3.9/lib/python3.9/site-packages/telegram/message.py", line 791, in reply_text
    return self.bot.send_message(
  File "/Library/Frameworks/Python.framework/Versions/3.9/lib/python3.9/site-packages/telegram/bot.py", line 130, in decorator
    result = func(*args, **kwargs)
  File "/Library/Frameworks/Python.framework/Versions/3.9/lib/python3.9/site-packages/telegram/bot.py", line 522, in send_message
    return self._message(  # type: ignore[return-value]
  File "/Library/Frameworks/Python.framework/Versions/3.9/lib/python3.9/site-packages/telegram/ext/extbot.py", line 200, in _message
    result = super()._message(
  File "/Library/Frameworks/Python.framework/Versions/3.9/lib/python3.9/site-packages/telegram/bot.py", line 336, in _message
    result = self._post(endpoint, data, timeout=timeout, api_kwargs=api_kwargs)
  File "/Library/Frameworks/Python.framework/Versions/3.9/lib/python3.9/site-packages/telegram/bot.py", line 295, in _post
    return self.request.post(
  File "/Library/Frameworks/Python.framework/Versions/3.9/lib/python3.9/site-packages/telegram/utils/request.py", line 361, in post
    result = self._request_wrapper(
  File "/Library/Frameworks/Python.framework/Versions/3.9/lib/python3.9/site-packages/telegram/utils/request.py", line 279, in _request_wrapper
    raise BadRequest(message)
telegram.error.BadRequest: Can't parse keyboard button: field "text" must be of type string
INFO:telegram.ext.updater:Received signal 2 (SIGINT), stopping...
INFO:apscheduler.scheduler:Scheduler has been shut down
WARNING:telegram.ext.updater:Exiting immediately!
INFO:root:BOT starting... Date: Mon Mar  7 17:24:19 2022
INFO:apscheduler.scheduler:Scheduler started
ERROR:telegram.ext.dispatcher:No error handlers are registered, logging exception.
Traceback (most recent call last):
  File "/Library/Frameworks/Python.framework/Versions/3.9/lib/python3.9/site-packages/telegram/ext/dispatcher.py", line 555, in process_update
    handler.handle_update(update, self, check, context)
  File "/Library/Frameworks/Python.framework/Versions/3.9/lib/python3.9/site-packages/telegram/ext/handler.py", line 198, in handle_update
    return self.callback(update, context)
  File "/Users/anastasiyasundeeva/learnpython/mybot/handlers.py", line 38, in vacansies_list
    update.message.reply_text(f'{text}',reply_markup= vacansies_keyboard())
  File "/Library/Frameworks/Python.framework/Versions/3.9/lib/python3.9/site-packages/telegram/message.py", line 791, in reply_text
    return self.bot.send_message(
  File "/Library/Frameworks/Python.framework/Versions/3.9/lib/python3.9/site-packages/telegram/bot.py", line 130, in decorator
    result = func(*args, **kwargs)
  File "/Library/Frameworks/Python.framework/Versions/3.9/lib/python3.9/site-packages/telegram/bot.py", line 522, in send_message
    return self._message(  # type: ignore[return-value]
  File "/Library/Frameworks/Python.framework/Versions/3.9/lib/python3.9/site-packages/telegram/ext/extbot.py", line 200, in _message
    result = super()._message(
  File "/Library/Frameworks/Python.framework/Versions/3.9/lib/python3.9/site-packages/telegram/bot.py", line 336, in _message
    result = self._post(endpoint, data, timeout=timeout, api_kwargs=api_kwargs)
  File "/Library/Frameworks/Python.framework/Versions/3.9/lib/python3.9/site-packages/telegram/bot.py", line 295, in _post
    return self.request.post(
  File "/Library/Frameworks/Python.framework/Versions/3.9/lib/python3.9/site-packages/telegram/utils/request.py", line 361, in post
    result = self._request_wrapper(
  File "/Library/Frameworks/Python.framework/Versions/3.9/lib/python3.9/site-packages/telegram/utils/request.py", line 279, in _request_wrapper
    raise BadRequest(message)
telegram.error.BadRequest: Can't parse keyboard button: field "text" must be of type string
ERROR:telegram.ext.dispatcher:No error handlers are registered, logging exception.
Traceback (most recent call last):
  File "/Library/Frameworks/Python.framework/Versions/3.9/lib/python3.9/site-packages/telegram/ext/dispatcher.py", line 555, in process_update
    handler.handle_update(update, self, check, context)
  File "/Library/Frameworks/Python.framework/Versions/3.9/lib/python3.9/site-packages/telegram/ext/handler.py", line 198, in handle_update
    return self.callback(update, context)
  File "/Users/anastasiyasundeeva/learnpython/mybot/handlers.py", line 38, in vacansies_list
    update.message.reply_text(f'{text}',reply_markup= vacansies_keyboard())
  File "/Library/Frameworks/Python.framework/Versions/3.9/lib/python3.9/site-packages/telegram/message.py", line 791, in reply_text
    return self.bot.send_message(
  File "/Library/Frameworks/Python.framework/Versions/3.9/lib/python3.9/site-packages/telegram/bot.py", line 130, in decorator
    result = func(*args, **kwargs)
  File "/Library/Frameworks/Python.framework/Versions/3.9/lib/python3.9/site-packages/telegram/bot.py", line 522, in send_message
    return self._message(  # type: ignore[return-value]
  File "/Library/Frameworks/Python.framework/Versions/3.9/lib/python3.9/site-packages/telegram/ext/extbot.py", line 200, in _message
    result = super()._message(
  File "/Library/Frameworks/Python.framework/Versions/3.9/lib/python3.9/site-packages/telegram/bot.py", line 336, in _message
    result = self._post(endpoint, data, timeout=timeout, api_kwargs=api_kwargs)
  File "/Library/Frameworks/Python.framework/Versions/3.9/lib/python3.9/site-packages/telegram/bot.py", line 295, in _post
    return self.request.post(
  File "/Library/Frameworks/Python.framework/Versions/3.9/lib/python3.9/site-packages/telegram/utils/request.py", line 361, in post
    result = self._request_wrapper(
  File "/Library/Frameworks/Python.framework/Versions/3.9/lib/python3.9/site-packages/telegram/utils/request.py", line 279, in _request_wrapper
    raise BadRequest(message)
telegram.error.BadRequest: Can't parse keyboard button: field "text" must be of type string
ERROR:telegram.ext.dispatcher:No error handlers are registered, logging exception.
Traceback (most recent call last):
  File "/Library/Frameworks/Python.framework/Versions/3.9/lib/python3.9/site-packages/telegram/ext/dispatcher.py", line 555, in process_update
    handler.handle_update(update, self, check, context)
  File "/Library/Frameworks/Python.framework/Versions/3.9/lib/python3.9/site-packages/telegram/ext/handler.py", line 198, in handle_update
    return self.callback(update, context)
  File "/Users/anastasiyasundeeva/learnpython/mybot/handlers.py", line 38, in vacansies_list
    update.message.reply_text(f'{text}',reply_markup= vacansies_keyboard())
  File "/Library/Frameworks/Python.framework/Versions/3.9/lib/python3.9/site-packages/telegram/message.py", line 791, in reply_text
    return self.bot.send_message(
  File "/Library/Frameworks/Python.framework/Versions/3.9/lib/python3.9/site-packages/telegram/bot.py", line 130, in decorator
    result = func(*args, **kwargs)
  File "/Library/Frameworks/Python.framework/Versions/3.9/lib/python3.9/site-packages/telegram/bot.py", line 522, in send_message
    return self._message(  # type: ignore[return-value]
  File "/Library/Frameworks/Python.framework/Versions/3.9/lib/python3.9/site-packages/telegram/ext/extbot.py", line 200, in _message
    result = super()._message(
  File "/Library/Frameworks/Python.framework/Versions/3.9/lib/python3.9/site-packages/telegram/bot.py", line 336, in _message
    result = self._post(endpoint, data, timeout=timeout, api_kwargs=api_kwargs)
  File "/Library/Frameworks/Python.framework/Versions/3.9/lib/python3.9/site-packages/telegram/bot.py", line 295, in _post
    return self.request.post(
  File "/Library/Frameworks/Python.framework/Versions/3.9/lib/python3.9/site-packages/telegram/utils/request.py", line 361, in post
    result = self._request_wrapper(
  File "/Library/Frameworks/Python.framework/Versions/3.9/lib/python3.9/site-packages/telegram/utils/request.py", line 279, in _request_wrapper
    raise BadRequest(message)
telegram.error.BadRequest: Can't parse keyboard button: field "text" must be of type string
INFO:telegram.ext.updater:Received signal 2 (SIGINT), stopping...
INFO:apscheduler.scheduler:Scheduler has been shut down
WARNING:telegram.ext.updater:Exiting immediately!
INFO:root:BOT starting... Date: Mon Mar  7 17:27:06 2022
INFO:apscheduler.scheduler:Scheduler started
INFO:telegram.ext.updater:Received signal 2 (SIGINT), stopping...
INFO:apscheduler.scheduler:Scheduler has been shut down
WARNING:telegram.ext.updater:Exiting immediately!
INFO:root:BOT starting... Date: Mon Mar  7 17:28:48 2022
INFO:apscheduler.scheduler:Scheduler started
INFO:telegram.ext.updater:Received signal 2 (SIGINT), stopping...
INFO:apscheduler.scheduler:Scheduler has been shut down
WARNING:telegram.ext.updater:Exiting immediately!
INFO:root:BOT starting... Date: Mon Mar  7 17:29:55 2022
INFO:apscheduler.scheduler:Scheduler started
INFO:telegram.ext.updater:Received signal 2 (SIGINT), stopping...
INFO:apscheduler.scheduler:Scheduler has been shut down
WARNING:telegram.ext.updater:Exiting immediately!
INFO:root:BOT starting... Date: Mon Mar  7 17:31:43 2022
INFO:apscheduler.scheduler:Scheduler started
INFO:telegram.ext.updater:Received signal 2 (SIGINT), stopping...
INFO:apscheduler.scheduler:Scheduler has been shut down
WARNING:telegram.ext.updater:Exiting immediately!
INFO:root:BOT starting... Date: Tue Mar  8 20:57:40 2022
INFO:apscheduler.scheduler:Scheduler started
INFO:telegram.ext.updater:Received signal 2 (SIGINT), stopping...
INFO:apscheduler.scheduler:Scheduler has been shut down
WARNING:telegram.ext.updater:Exiting immediately!
INFO:root:BOT starting... Date: Sat Mar 12 12:58:00 2022
INFO:apscheduler.scheduler:Scheduler started
INFO:telegram.ext.updater:Received signal 2 (SIGINT), stopping...
INFO:apscheduler.scheduler:Scheduler has been shut down
WARNING:telegram.ext.updater:Exiting immediately!
INFO:root:BOT starting... Date: Sat Mar 12 13:03:56 2022
INFO:apscheduler.scheduler:Scheduler started
WARNING:telegram.vendor.ptb_urllib3.urllib3.connectionpool:Retrying (Retry(total=2, connect=None, read=None, redirect=None)) after connection broken by 'ConnectTimeoutError(<telegram.vendor.ptb_urllib3.urllib3.connection.VerifiedHTTPSConnection object at 0x7fb67ed3cac0>, 'Connection to api.telegram.org timed out. (connect timeout=5.0)')': /bot5196914876:AAHeANqoy4sOKsF04EjsZZhxQGruBIDKeks/getUpdates
WARNING:telegram.vendor.ptb_urllib3.urllib3.connectionpool:Retrying (Retry(total=1, connect=None, read=None, redirect=None)) after connection broken by 'ConnectTimeoutError(<telegram.vendor.ptb_urllib3.urllib3.connection.VerifiedHTTPSConnection object at 0x7fb67ed3c040>, 'Connection to api.telegram.org timed out. (connect timeout=5.0)')': /bot5196914876:AAHeANqoy4sOKsF04EjsZZhxQGruBIDKeks/getUpdates
WARNING:telegram.vendor.ptb_urllib3.urllib3.connectionpool:Retrying (Retry(total=0, connect=None, read=None, redirect=None)) after connection broken by 'ConnectTimeoutError(<telegram.vendor.ptb_urllib3.urllib3.connection.VerifiedHTTPSConnection object at 0x7fb67ed3ce80>, 'Connection to api.telegram.org timed out. (connect timeout=5.0)')': /bot5196914876:AAHeANqoy4sOKsF04EjsZZhxQGruBIDKeks/getUpdates
ERROR:telegram.ext.updater:Error while getting Updates: urllib3 HTTPError HTTPSConnectionPool(host='api.telegram.org', port=443): Max retries exceeded with url: /bot5196914876:AAHeANqoy4sOKsF04EjsZZhxQGruBIDKeks/getUpdates (Caused by ConnectTimeoutError(<telegram.vendor.ptb_urllib3.urllib3.connection.VerifiedHTTPSConnection object at 0x7fb67ed3cdf0>, 'Connection to api.telegram.org timed out. (connect timeout=5.0)'))
ERROR:telegram.ext.dispatcher:No error handlers are registered, logging exception.
Traceback (most recent call last):
  File "/Library/Frameworks/Python.framework/Versions/3.9/lib/python3.9/site-packages/telegram/vendor/ptb_urllib3/urllib3/connection.py", line 140, in _new_conn
    conn = connection.create_connection(
  File "/Library/Frameworks/Python.framework/Versions/3.9/lib/python3.9/site-packages/telegram/vendor/ptb_urllib3/urllib3/util/connection.py", line 83, in create_connection
    raise err
  File "/Library/Frameworks/Python.framework/Versions/3.9/lib/python3.9/site-packages/telegram/vendor/ptb_urllib3/urllib3/util/connection.py", line 73, in create_connection
    sock.connect(sa)
socket.timeout: timed out

During handling of the above exception, another exception occurred:

Traceback (most recent call last):
  File "/Library/Frameworks/Python.framework/Versions/3.9/lib/python3.9/site-packages/telegram/vendor/ptb_urllib3/urllib3/connectionpool.py", line 614, in urlopen
    httplib_response = self._make_request(conn, method, url,
  File "/Library/Frameworks/Python.framework/Versions/3.9/lib/python3.9/site-packages/telegram/vendor/ptb_urllib3/urllib3/connectionpool.py", line 360, in _make_request
    self._validate_conn(conn)
  File "/Library/Frameworks/Python.framework/Versions/3.9/lib/python3.9/site-packages/telegram/vendor/ptb_urllib3/urllib3/connectionpool.py", line 857, in _validate_conn
    super(HTTPSConnectionPool, self)._validate_conn(conn)
  File "/Library/Frameworks/Python.framework/Versions/3.9/lib/python3.9/site-packages/telegram/vendor/ptb_urllib3/urllib3/connectionpool.py", line 289, in _validate_conn
    conn.connect()
  File "/Library/Frameworks/Python.framework/Versions/3.9/lib/python3.9/site-packages/telegram/vendor/ptb_urllib3/urllib3/connection.py", line 284, in connect
    conn = self._new_conn()
  File "/Library/Frameworks/Python.framework/Versions/3.9/lib/python3.9/site-packages/telegram/vendor/ptb_urllib3/urllib3/connection.py", line 144, in _new_conn
    raise ConnectTimeoutError(
telegram.vendor.ptb_urllib3.urllib3.exceptions.ConnectTimeoutError: (<telegram.vendor.ptb_urllib3.urllib3.connection.VerifiedHTTPSConnection object at 0x7fb67ed3cdf0>, 'Connection to api.telegram.org timed out. (connect timeout=5.0)')

During handling of the above exception, another exception occurred:

Traceback (most recent call last):
  File "/Library/Frameworks/Python.framework/Versions/3.9/lib/python3.9/site-packages/telegram/utils/request.py", line 259, in _request_wrapper
    resp = self._con_pool.request(*args, **kwargs)
  File "/Library/Frameworks/Python.framework/Versions/3.9/lib/python3.9/site-packages/telegram/vendor/ptb_urllib3/urllib3/request.py", line 68, in request
    return self.request_encode_body(method, url, fields=fields,
  File "/Library/Frameworks/Python.framework/Versions/3.9/lib/python3.9/site-packages/telegram/vendor/ptb_urllib3/urllib3/request.py", line 148, in request_encode_body
    return self.urlopen(method, url, **extra_kw)
  File "/Library/Frameworks/Python.framework/Versions/3.9/lib/python3.9/site-packages/telegram/vendor/ptb_urllib3/urllib3/poolmanager.py", line 244, in urlopen
    response = conn.urlopen(method, u.request_uri, **kw)
  File "/Library/Frameworks/Python.framework/Versions/3.9/lib/python3.9/site-packages/telegram/vendor/ptb_urllib3/urllib3/connectionpool.py", line 691, in urlopen
    return self.urlopen(method, url, body, headers, retries,
  File "/Library/Frameworks/Python.framework/Versions/3.9/lib/python3.9/site-packages/telegram/vendor/ptb_urllib3/urllib3/connectionpool.py", line 691, in urlopen
    return self.urlopen(method, url, body, headers, retries,
  File "/Library/Frameworks/Python.framework/Versions/3.9/lib/python3.9/site-packages/telegram/vendor/ptb_urllib3/urllib3/connectionpool.py", line 691, in urlopen
    return self.urlopen(method, url, body, headers, retries,
  File "/Library/Frameworks/Python.framework/Versions/3.9/lib/python3.9/site-packages/telegram/vendor/ptb_urllib3/urllib3/connectionpool.py", line 665, in urlopen
    retries = retries.increment(method, url, error=e, _pool=self,
  File "/Library/Frameworks/Python.framework/Versions/3.9/lib/python3.9/site-packages/telegram/vendor/ptb_urllib3/urllib3/util/retry.py", line 376, in increment
    raise MaxRetryError(_pool, url, error or ResponseError(cause))
telegram.vendor.ptb_urllib3.urllib3.exceptions.MaxRetryError: HTTPSConnectionPool(host='api.telegram.org', port=443): Max retries exceeded with url: /bot5196914876:AAHeANqoy4sOKsF04EjsZZhxQGruBIDKeks/getUpdates (Caused by ConnectTimeoutError(<telegram.vendor.ptb_urllib3.urllib3.connection.VerifiedHTTPSConnection object at 0x7fb67ed3cdf0>, 'Connection to api.telegram.org timed out. (connect timeout=5.0)'))

The above exception was the direct cause of the following exception:

Traceback (most recent call last):
  File "/Library/Frameworks/Python.framework/Versions/3.9/lib/python3.9/site-packages/telegram/ext/updater.py", line 646, in _network_loop_retry
    if not action_cb():
  File "/Library/Frameworks/Python.framework/Versions/3.9/lib/python3.9/site-packages/telegram/ext/updater.py", line 597, in polling_action_cb
    updates = self.bot.get_updates(
  File "/Library/Frameworks/Python.framework/Versions/3.9/lib/python3.9/site-packages/telegram/ext/extbot.py", line 224, in get_updates
    updates = super().get_updates(
  File "/Library/Frameworks/Python.framework/Versions/3.9/lib/python3.9/site-packages/telegram/bot.py", line 130, in decorator
    result = func(*args, **kwargs)
  File "/Library/Frameworks/Python.framework/Versions/3.9/lib/python3.9/site-packages/telegram/bot.py", line 3054, in get_updates
    self._post(
  File "/Library/Frameworks/Python.framework/Versions/3.9/lib/python3.9/site-packages/telegram/bot.py", line 295, in _post
    return self.request.post(
  File "/Library/Frameworks/Python.framework/Versions/3.9/lib/python3.9/site-packages/telegram/utils/request.py", line 361, in post
    result = self._request_wrapper(
  File "/Library/Frameworks/Python.framework/Versions/3.9/lib/python3.9/site-packages/telegram/utils/request.py", line 265, in _request_wrapper
    raise NetworkError(f'urllib3 HTTPError {error}') from error
telegram.error.NetworkError: urllib3 HTTPError HTTPSConnectionPool(host='api.telegram.org', port=443): Max retries exceeded with url: /bot5196914876:AAHeANqoy4sOKsF04EjsZZhxQGruBIDKeks/getUpdates (Caused by ConnectTimeoutError(<telegram.vendor.ptb_urllib3.urllib3.connection.VerifiedHTTPSConnection object at 0x7fb67ed3cdf0>, 'Connection to api.telegram.org timed out. (connect timeout=5.0)'))
WARNING:telegram.vendor.ptb_urllib3.urllib3.connectionpool:Retrying (Retry(total=2, connect=None, read=None, redirect=None)) after connection broken by 'ConnectTimeoutError(<telegram.vendor.ptb_urllib3.urllib3.connection.VerifiedHTTPSConnection object at 0x7fb67ed20bb0>, 'Connection to api.telegram.org timed out. (connect timeout=5.0)')': /bot5196914876:AAHeANqoy4sOKsF04EjsZZhxQGruBIDKeks/getUpdates
WARNING:telegram.vendor.ptb_urllib3.urllib3.connectionpool:Retrying (Retry(total=1, connect=None, read=None, redirect=None)) after connection broken by 'ConnectTimeoutError(<telegram.vendor.ptb_urllib3.urllib3.connection.VerifiedHTTPSConnection object at 0x7fb67ed5d400>, 'Connection to api.telegram.org timed out. (connect timeout=5.0)')': /bot5196914876:AAHeANqoy4sOKsF04EjsZZhxQGruBIDKeks/getUpdates
WARNING:telegram.vendor.ptb_urllib3.urllib3.connectionpool:Retrying (Retry(total=0, connect=None, read=None, redirect=None)) after connection broken by 'ConnectTimeoutError(<telegram.vendor.ptb_urllib3.urllib3.connection.VerifiedHTTPSConnection object at 0x7fb67ed5d550>, 'Connection to api.telegram.org timed out. (connect timeout=5.0)')': /bot5196914876:AAHeANqoy4sOKsF04EjsZZhxQGruBIDKeks/getUpdates
ERROR:telegram.ext.updater:Error while getting Updates: urllib3 HTTPError HTTPSConnectionPool(host='api.telegram.org', port=443): Max retries exceeded with url: /bot5196914876:AAHeANqoy4sOKsF04EjsZZhxQGruBIDKeks/getUpdates (Caused by ConnectTimeoutError(<telegram.vendor.ptb_urllib3.urllib3.connection.VerifiedHTTPSConnection object at 0x7fb67ed5d670>, 'Connection to api.telegram.org timed out. (connect timeout=5.0)'))
ERROR:telegram.ext.dispatcher:No error handlers are registered, logging exception.
Traceback (most recent call last):
  File "/Library/Frameworks/Python.framework/Versions/3.9/lib/python3.9/site-packages/telegram/vendor/ptb_urllib3/urllib3/connection.py", line 140, in _new_conn
    conn = connection.create_connection(
  File "/Library/Frameworks/Python.framework/Versions/3.9/lib/python3.9/site-packages/telegram/vendor/ptb_urllib3/urllib3/util/connection.py", line 83, in create_connection
    raise err
  File "/Library/Frameworks/Python.framework/Versions/3.9/lib/python3.9/site-packages/telegram/vendor/ptb_urllib3/urllib3/util/connection.py", line 73, in create_connection
    sock.connect(sa)
socket.timeout: timed out

During handling of the above exception, another exception occurred:

Traceback (most recent call last):
  File "/Library/Frameworks/Python.framework/Versions/3.9/lib/python3.9/site-packages/telegram/vendor/ptb_urllib3/urllib3/connectionpool.py", line 614, in urlopen
    httplib_response = self._make_request(conn, method, url,
  File "/Library/Frameworks/Python.framework/Versions/3.9/lib/python3.9/site-packages/telegram/vendor/ptb_urllib3/urllib3/connectionpool.py", line 360, in _make_request
    self._validate_conn(conn)
  File "/Library/Frameworks/Python.framework/Versions/3.9/lib/python3.9/site-packages/telegram/vendor/ptb_urllib3/urllib3/connectionpool.py", line 857, in _validate_conn
    super(HTTPSConnectionPool, self)._validate_conn(conn)
  File "/Library/Frameworks/Python.framework/Versions/3.9/lib/python3.9/site-packages/telegram/vendor/ptb_urllib3/urllib3/connectionpool.py", line 289, in _validate_conn
    conn.connect()
  File "/Library/Frameworks/Python.framework/Versions/3.9/lib/python3.9/site-packages/telegram/vendor/ptb_urllib3/urllib3/connection.py", line 284, in connect
    conn = self._new_conn()
  File "/Library/Frameworks/Python.framework/Versions/3.9/lib/python3.9/site-packages/telegram/vendor/ptb_urllib3/urllib3/connection.py", line 144, in _new_conn
    raise ConnectTimeoutError(
telegram.vendor.ptb_urllib3.urllib3.exceptions.ConnectTimeoutError: (<telegram.vendor.ptb_urllib3.urllib3.connection.VerifiedHTTPSConnection object at 0x7fb67ed5d670>, 'Connection to api.telegram.org timed out. (connect timeout=5.0)')

During handling of the above exception, another exception occurred:

Traceback (most recent call last):
  File "/Library/Frameworks/Python.framework/Versions/3.9/lib/python3.9/site-packages/telegram/utils/request.py", line 259, in _request_wrapper
    resp = self._con_pool.request(*args, **kwargs)
  File "/Library/Frameworks/Python.framework/Versions/3.9/lib/python3.9/site-packages/telegram/vendor/ptb_urllib3/urllib3/request.py", line 68, in request
    return self.request_encode_body(method, url, fields=fields,
  File "/Library/Frameworks/Python.framework/Versions/3.9/lib/python3.9/site-packages/telegram/vendor/ptb_urllib3/urllib3/request.py", line 148, in request_encode_body
    return self.urlopen(method, url, **extra_kw)
  File "/Library/Frameworks/Python.framework/Versions/3.9/lib/python3.9/site-packages/telegram/vendor/ptb_urllib3/urllib3/poolmanager.py", line 244, in urlopen
    response = conn.urlopen(method, u.request_uri, **kw)
  File "/Library/Frameworks/Python.framework/Versions/3.9/lib/python3.9/site-packages/telegram/vendor/ptb_urllib3/urllib3/connectionpool.py", line 691, in urlopen
    return self.urlopen(method, url, body, headers, retries,
  File "/Library/Frameworks/Python.framework/Versions/3.9/lib/python3.9/site-packages/telegram/vendor/ptb_urllib3/urllib3/connectionpool.py", line 691, in urlopen
    return self.urlopen(method, url, body, headers, retries,
  File "/Library/Frameworks/Python.framework/Versions/3.9/lib/python3.9/site-packages/telegram/vendor/ptb_urllib3/urllib3/connectionpool.py", line 691, in urlopen
    return self.urlopen(method, url, body, headers, retries,
  File "/Library/Frameworks/Python.framework/Versions/3.9/lib/python3.9/site-packages/telegram/vendor/ptb_urllib3/urllib3/connectionpool.py", line 665, in urlopen
    retries = retries.increment(method, url, error=e, _pool=self,
  File "/Library/Frameworks/Python.framework/Versions/3.9/lib/python3.9/site-packages/telegram/vendor/ptb_urllib3/urllib3/util/retry.py", line 376, in increment
    raise MaxRetryError(_pool, url, error or ResponseError(cause))
telegram.vendor.ptb_urllib3.urllib3.exceptions.MaxRetryError: HTTPSConnectionPool(host='api.telegram.org', port=443): Max retries exceeded with url: /bot5196914876:AAHeANqoy4sOKsF04EjsZZhxQGruBIDKeks/getUpdates (Caused by ConnectTimeoutError(<telegram.vendor.ptb_urllib3.urllib3.connection.VerifiedHTTPSConnection object at 0x7fb67ed5d670>, 'Connection to api.telegram.org timed out. (connect timeout=5.0)'))

The above exception was the direct cause of the following exception:

Traceback (most recent call last):
  File "/Library/Frameworks/Python.framework/Versions/3.9/lib/python3.9/site-packages/telegram/ext/updater.py", line 646, in _network_loop_retry
    if not action_cb():
  File "/Library/Frameworks/Python.framework/Versions/3.9/lib/python3.9/site-packages/telegram/ext/updater.py", line 597, in polling_action_cb
    updates = self.bot.get_updates(
  File "/Library/Frameworks/Python.framework/Versions/3.9/lib/python3.9/site-packages/telegram/ext/extbot.py", line 224, in get_updates
    updates = super().get_updates(
  File "/Library/Frameworks/Python.framework/Versions/3.9/lib/python3.9/site-packages/telegram/bot.py", line 130, in decorator
    result = func(*args, **kwargs)
  File "/Library/Frameworks/Python.framework/Versions/3.9/lib/python3.9/site-packages/telegram/bot.py", line 3054, in get_updates
    self._post(
  File "/Library/Frameworks/Python.framework/Versions/3.9/lib/python3.9/site-packages/telegram/bot.py", line 295, in _post
    return self.request.post(
  File "/Library/Frameworks/Python.framework/Versions/3.9/lib/python3.9/site-packages/telegram/utils/request.py", line 361, in post
    result = self._request_wrapper(
  File "/Library/Frameworks/Python.framework/Versions/3.9/lib/python3.9/site-packages/telegram/utils/request.py", line 265, in _request_wrapper
    raise NetworkError(f'urllib3 HTTPError {error}') from error
telegram.error.NetworkError: urllib3 HTTPError HTTPSConnectionPool(host='api.telegram.org', port=443): Max retries exceeded with url: /bot5196914876:AAHeANqoy4sOKsF04EjsZZhxQGruBIDKeks/getUpdates (Caused by ConnectTimeoutError(<telegram.vendor.ptb_urllib3.urllib3.connection.VerifiedHTTPSConnection object at 0x7fb67ed5d670>, 'Connection to api.telegram.org timed out. (connect timeout=5.0)'))
INFO:telegram.ext.updater:Received signal 2 (SIGINT), stopping...
INFO:apscheduler.scheduler:Scheduler has been shut down
INFO:root:BOT starting... Date: Sat Mar 12 13:25:04 2022
INFO:apscheduler.scheduler:Scheduler started
INFO:telegram.ext.updater:Received signal 2 (SIGINT), stopping...
INFO:apscheduler.scheduler:Scheduler has been shut down
WARNING:telegram.ext.updater:Exiting immediately!
INFO:root:BOT starting... Date: Sat Mar 12 13:25:56 2022
INFO:apscheduler.scheduler:Scheduler started
INFO:telegram.ext.updater:Received signal 2 (SIGINT), stopping...
INFO:apscheduler.scheduler:Scheduler has been shut down
WARNING:telegram.ext.updater:Exiting immediately!
INFO:root:BOT starting... Date: Sat Mar 12 13:31:34 2022
INFO:apscheduler.scheduler:Scheduler started
INFO:telegram.ext.updater:Received signal 2 (SIGINT), stopping...
INFO:apscheduler.scheduler:Scheduler has been shut down
WARNING:telegram.ext.updater:Exiting immediately!
INFO:root:BOT starting... Date: Sat Mar 12 13:35:02 2022
INFO:apscheduler.scheduler:Scheduler started
INFO:telegram.ext.updater:Received signal 2 (SIGINT), stopping...
INFO:apscheduler.scheduler:Scheduler has been shut down
WARNING:telegram.ext.updater:Exiting immediately!
INFO:root:BOT starting... Date: Sat Mar 12 13:37:25 2022
INFO:apscheduler.scheduler:Scheduler started
INFO:telegram.ext.updater:Received signal 2 (SIGINT), stopping...
INFO:apscheduler.scheduler:Scheduler has been shut down
INFO:root:BOT starting... Date: Sat Mar 12 13:41:52 2022
INFO:apscheduler.scheduler:Scheduler started
INFO:root:BOT starting... Date: Sat Mar 12 15:46:13 2022
INFO:apscheduler.scheduler:Scheduler started
INFO:telegram.ext.updater:Received signal 2 (SIGINT), stopping...
INFO:apscheduler.scheduler:Scheduler has been shut down
WARNING:telegram.ext.updater:Exiting immediately!
INFO:root:BOT starting... Date: Sat Mar 12 16:04:54 2022
INFO:apscheduler.scheduler:Scheduler started
ERROR:telegram.ext.dispatcher:No error handlers are registered, logging exception.
Traceback (most recent call last):
  File "/Library/Frameworks/Python.framework/Versions/3.9/lib/python3.9/site-packages/telegram/ext/dispatcher.py", line 555, in process_update
    handler.handle_update(update, self, check, context)
  File "/Library/Frameworks/Python.framework/Versions/3.9/lib/python3.9/site-packages/telegram/ext/handler.py", line 198, in handle_update
    return self.callback(update, context)
TypeError: start expected at most 1 argument, got 2
ERROR:telegram.ext.dispatcher:No error handlers are registered, logging exception.
Traceback (most recent call last):
  File "/Library/Frameworks/Python.framework/Versions/3.9/lib/python3.9/site-packages/telegram/ext/dispatcher.py", line 555, in process_update
    handler.handle_update(update, self, check, context)
  File "/Library/Frameworks/Python.framework/Versions/3.9/lib/python3.9/site-packages/telegram/ext/handler.py", line 198, in handle_update
    return self.callback(update, context)
TypeError: start expected at most 1 argument, got 2
ERROR:telegram.ext.dispatcher:No error handlers are registered, logging exception.
Traceback (most recent call last):
  File "/Library/Frameworks/Python.framework/Versions/3.9/lib/python3.9/site-packages/telegram/ext/dispatcher.py", line 555, in process_update
    handler.handle_update(update, self, check, context)
  File "/Library/Frameworks/Python.framework/Versions/3.9/lib/python3.9/site-packages/telegram/ext/handler.py", line 198, in handle_update
    return self.callback(update, context)
TypeError: start expected at most 1 argument, got 2
INFO:telegram.ext.updater:Received signal 2 (SIGINT), stopping...
INFO:apscheduler.scheduler:Scheduler has been shut down
WARNING:telegram.ext.updater:Exiting immediately!
INFO:root:BOT starting... Date: Sat Mar 12 16:32:32 2022
INFO:apscheduler.scheduler:Scheduler started
ERROR:telegram.ext.dispatcher:No error handlers are registered, logging exception.
Traceback (most recent call last):
  File "/Library/Frameworks/Python.framework/Versions/3.9/lib/python3.9/site-packages/telegram/ext/dispatcher.py", line 555, in process_update
    handler.handle_update(update, self, check, context)
  File "/Library/Frameworks/Python.framework/Versions/3.9/lib/python3.9/site-packages/telegram/ext/handler.py", line 198, in handle_update
    return self.callback(update, context)
  File "/Users/anastasiyasundeeva/learnpython/2mybot/handlers.py", line 18, in start
    reply_markup = ReplyKeyboardMarkup(keyboard)
NameError: name 'ReplyKeyboardMarkup' is not defined
INFO:telegram.ext.updater:Received signal 2 (SIGINT), stopping...
INFO:apscheduler.scheduler:Scheduler has been shut down
WARNING:telegram.ext.updater:Exiting immediately!
INFO:root:BOT starting... Date: Sat Mar 12 16:40:10 2022
INFO:apscheduler.scheduler:Scheduler started
INFO:telegram.ext.updater:Received signal 2 (SIGINT), stopping...
INFO:apscheduler.scheduler:Scheduler has been shut down
WARNING:telegram.ext.updater:Exiting immediately!
INFO:root:BOT starting... Date: Sat Mar 12 17:41:15 2022
INFO:apscheduler.scheduler:Scheduler started
ERROR:telegram.ext.dispatcher:No error handlers are registered, logging exception.
Traceback (most recent call last):
  File "/Library/Frameworks/Python.framework/Versions/3.9/lib/python3.9/site-packages/telegram/ext/dispatcher.py", line 555, in process_update
    handler.handle_update(update, self, check, context)
  File "/Library/Frameworks/Python.framework/Versions/3.9/lib/python3.9/site-packages/telegram/ext/conversationhandler.py", line 626, in handle_update
    new_state = handler.handle_update(update, dispatcher, check_result, context)
  File "/Library/Frameworks/Python.framework/Versions/3.9/lib/python3.9/site-packages/telegram/ext/handler.py", line 198, in handle_update
    return self.callback(update, context)
  File "/Users/anastasiyasundeeva/learnpython/2mybot/anketa.py", line 5, in anketa_start
    update.message.reply_text (
  File "/Library/Frameworks/Python.framework/Versions/3.9/lib/python3.9/site-packages/telegram/message.py", line 791, in reply_text
    return self.bot.send_message(
  File "/Library/Frameworks/Python.framework/Versions/3.9/lib/python3.9/site-packages/telegram/bot.py", line 130, in decorator
    result = func(*args, **kwargs)
  File "/Library/Frameworks/Python.framework/Versions/3.9/lib/python3.9/site-packages/telegram/bot.py", line 522, in send_message
    return self._message(  # type: ignore[return-value]
  File "/Library/Frameworks/Python.framework/Versions/3.9/lib/python3.9/site-packages/telegram/ext/extbot.py", line 200, in _message
    result = super()._message(
  File "/Library/Frameworks/Python.framework/Versions/3.9/lib/python3.9/site-packages/telegram/bot.py", line 336, in _message
    result = self._post(endpoint, data, timeout=timeout, api_kwargs=api_kwargs)
  File "/Library/Frameworks/Python.framework/Versions/3.9/lib/python3.9/site-packages/telegram/bot.py", line 295, in _post
    return self.request.post(
  File "/Library/Frameworks/Python.framework/Versions/3.9/lib/python3.9/site-packages/telegram/utils/request.py", line 364, in post
    body=json.dumps(data).encode('utf-8'),
  File "/Library/Frameworks/Python.framework/Versions/3.9/lib/python3.9/json/__init__.py", line 231, in dumps
    return _default_encoder.encode(obj)
  File "/Library/Frameworks/Python.framework/Versions/3.9/lib/python3.9/json/encoder.py", line 199, in encode
    chunks = self.iterencode(o, _one_shot=True)
  File "/Library/Frameworks/Python.framework/Versions/3.9/lib/python3.9/json/encoder.py", line 257, in iterencode
    return _iterencode(o, 0)
  File "/Library/Frameworks/Python.framework/Versions/3.9/lib/python3.9/json/encoder.py", line 179, in default
    raise TypeError(f'Object of type {o.__class__.__name__} '
TypeError: Object of type type is not JSON serializable
ERROR:telegram.ext.dispatcher:No error handlers are registered, logging exception.
Traceback (most recent call last):
  File "/Library/Frameworks/Python.framework/Versions/3.9/lib/python3.9/site-packages/telegram/ext/dispatcher.py", line 555, in process_update
    handler.handle_update(update, self, check, context)
  File "/Library/Frameworks/Python.framework/Versions/3.9/lib/python3.9/site-packages/telegram/ext/conversationhandler.py", line 626, in handle_update
    new_state = handler.handle_update(update, dispatcher, check_result, context)
  File "/Library/Frameworks/Python.framework/Versions/3.9/lib/python3.9/site-packages/telegram/ext/handler.py", line 198, in handle_update
    return self.callback(update, context)
  File "/Users/anastasiyasundeeva/learnpython/2mybot/anketa.py", line 5, in anketa_start
    update.message.reply_text (
  File "/Library/Frameworks/Python.framework/Versions/3.9/lib/python3.9/site-packages/telegram/message.py", line 791, in reply_text
    return self.bot.send_message(
  File "/Library/Frameworks/Python.framework/Versions/3.9/lib/python3.9/site-packages/telegram/bot.py", line 130, in decorator
    result = func(*args, **kwargs)
  File "/Library/Frameworks/Python.framework/Versions/3.9/lib/python3.9/site-packages/telegram/bot.py", line 522, in send_message
    return self._message(  # type: ignore[return-value]
  File "/Library/Frameworks/Python.framework/Versions/3.9/lib/python3.9/site-packages/telegram/ext/extbot.py", line 200, in _message
    result = super()._message(
  File "/Library/Frameworks/Python.framework/Versions/3.9/lib/python3.9/site-packages/telegram/bot.py", line 336, in _message
    result = self._post(endpoint, data, timeout=timeout, api_kwargs=api_kwargs)
  File "/Library/Frameworks/Python.framework/Versions/3.9/lib/python3.9/site-packages/telegram/bot.py", line 295, in _post
    return self.request.post(
  File "/Library/Frameworks/Python.framework/Versions/3.9/lib/python3.9/site-packages/telegram/utils/request.py", line 364, in post
    body=json.dumps(data).encode('utf-8'),
  File "/Library/Frameworks/Python.framework/Versions/3.9/lib/python3.9/json/__init__.py", line 231, in dumps
    return _default_encoder.encode(obj)
  File "/Library/Frameworks/Python.framework/Versions/3.9/lib/python3.9/json/encoder.py", line 199, in encode
    chunks = self.iterencode(o, _one_shot=True)
  File "/Library/Frameworks/Python.framework/Versions/3.9/lib/python3.9/json/encoder.py", line 257, in iterencode
    return _iterencode(o, 0)
  File "/Library/Frameworks/Python.framework/Versions/3.9/lib/python3.9/json/encoder.py", line 179, in default
    raise TypeError(f'Object of type {o.__class__.__name__} '
TypeError: Object of type type is not JSON serializable
INFO:telegram.ext.updater:Received signal 2 (SIGINT), stopping...
INFO:apscheduler.scheduler:Scheduler has been shut down
INFO:root:BOT starting... Date: Sat Mar 12 17:44:32 2022
INFO:apscheduler.scheduler:Scheduler started
INFO:root:BOT starting... Date: Sat Mar 12 21:56:54 2022
INFO:apscheduler.scheduler:Scheduler started
INFO:telegram.ext.updater:Received signal 2 (SIGINT), stopping...
INFO:apscheduler.scheduler:Scheduler has been shut down
WARNING:telegram.ext.updater:Exiting immediately!
INFO:root:BOT starting... Date: Sat Mar 12 21:57:21 2022
INFO:apscheduler.scheduler:Scheduler started
INFO:telegram.ext.updater:Received signal 2 (SIGINT), stopping...
INFO:apscheduler.scheduler:Scheduler has been shut down
WARNING:telegram.ext.updater:Exiting immediately!
INFO:root:BOT starting... Date: Sat Mar 12 21:58:58 2022
INFO:apscheduler.scheduler:Scheduler started
ERROR:telegram.ext.dispatcher:No error handlers are registered, logging exception.
Traceback (most recent call last):
  File "/Library/Frameworks/Python.framework/Versions/3.9/lib/python3.9/site-packages/telegram/ext/dispatcher.py", line 555, in process_update
    handler.handle_update(update, self, check, context)
  File "/Library/Frameworks/Python.framework/Versions/3.9/lib/python3.9/site-packages/telegram/ext/handler.py", line 198, in handle_update
    return self.callback(update, context)
  File "/Users/anastasiyasundeeva/learnpython/2mybot/handlers.py", line 18, in start
    reply_markup = ReplyKeyboardMarkup(keyboard)
NameError: name 'ReplyKeyboardMarkup' is not defined
INFO:telegram.ext.updater:Received signal 2 (SIGINT), stopping...
INFO:apscheduler.scheduler:Scheduler has been shut down
WARNING:telegram.ext.updater:Exiting immediately!
INFO:root:BOT starting... Date: Sat Mar 12 22:00:39 2022
INFO:apscheduler.scheduler:Scheduler started
INFO:telegram.ext.updater:Received signal 2 (SIGINT), stopping...
INFO:apscheduler.scheduler:Scheduler has been shut down
WARNING:telegram.ext.updater:Exiting immediately!
INFO:root:BOT starting... Date: Sat Mar 12 22:03:27 2022
INFO:apscheduler.scheduler:Scheduler started
INFO:telegram.ext.updater:Received signal 2 (SIGINT), stopping...
INFO:apscheduler.scheduler:Scheduler has been shut down
WARNING:telegram.ext.updater:Exiting immediately!
INFO:root:BOT starting... Date: Sat Mar 12 22:09:11 2022
INFO:apscheduler.scheduler:Scheduler started
INFO:telegram.ext.updater:Received signal 2 (SIGINT), stopping...
INFO:apscheduler.scheduler:Scheduler has been shut down
WARNING:telegram.ext.updater:Exiting immediately!
INFO:root:BOT starting... Date: Sat Mar 12 22:15:46 2022
INFO:apscheduler.scheduler:Scheduler started
INFO:telegram.ext.updater:Received signal 2 (SIGINT), stopping...
INFO:apscheduler.scheduler:Scheduler has been shut down
WARNING:telegram.ext.updater:Exiting immediately!
INFO:root:BOT starting... Date: Sat Mar 12 22:18:25 2022
INFO:apscheduler.scheduler:Scheduler started
INFO:telegram.ext.updater:Received signal 2 (SIGINT), stopping...
INFO:apscheduler.scheduler:Scheduler has been shut down
INFO:root:BOT starting... Date: Sat Mar 12 22:29:32 2022
INFO:apscheduler.scheduler:Scheduler started
ERROR:telegram.ext.dispatcher:No error handlers are registered, logging exception.
Traceback (most recent call last):
  File "/Library/Frameworks/Python.framework/Versions/3.9/lib/python3.9/site-packages/telegram/ext/dispatcher.py", line 555, in process_update
    handler.handle_update(update, self, check, context)
  File "/Library/Frameworks/Python.framework/Versions/3.9/lib/python3.9/site-packages/telegram/ext/conversationhandler.py", line 626, in handle_update
    new_state = handler.handle_update(update, dispatcher, check_result, context)
  File "/Library/Frameworks/Python.framework/Versions/3.9/lib/python3.9/site-packages/telegram/ext/handler.py", line 198, in handle_update
    return self.callback(update, context)
  File "/Users/anastasiyasundeeva/learnpython/2mybot/anketa.py", line 25, in anketa_name
    return rating
NameError: name 'rating' is not defined
ERROR:telegram.ext.dispatcher:No error handlers are registered, logging exception.
Traceback (most recent call last):
  File "/Library/Frameworks/Python.framework/Versions/3.9/lib/python3.9/site-packages/telegram/ext/dispatcher.py", line 555, in process_update
    handler.handle_update(update, self, check, context)
  File "/Library/Frameworks/Python.framework/Versions/3.9/lib/python3.9/site-packages/telegram/ext/conversationhandler.py", line 626, in handle_update
    new_state = handler.handle_update(update, dispatcher, check_result, context)
  File "/Library/Frameworks/Python.framework/Versions/3.9/lib/python3.9/site-packages/telegram/ext/handler.py", line 198, in handle_update
    return self.callback(update, context)
  File "/Users/anastasiyasundeeva/learnpython/2mybot/anketa.py", line 25, in anketa_name
    return rating
NameError: name 'rating' is not defined
ERROR:telegram.ext.dispatcher:No error handlers are registered, logging exception.
Traceback (most recent call last):
  File "/Library/Frameworks/Python.framework/Versions/3.9/lib/python3.9/site-packages/telegram/ext/dispatcher.py", line 555, in process_update
    handler.handle_update(update, self, check, context)
  File "/Library/Frameworks/Python.framework/Versions/3.9/lib/python3.9/site-packages/telegram/ext/conversationhandler.py", line 626, in handle_update
    new_state = handler.handle_update(update, dispatcher, check_result, context)
  File "/Library/Frameworks/Python.framework/Versions/3.9/lib/python3.9/site-packages/telegram/ext/handler.py", line 198, in handle_update
    return self.callback(update, context)
  File "/Users/anastasiyasundeeva/learnpython/2mybot/anketa.py", line 25, in anketa_name
    return rating
NameError: name 'rating' is not defined
ERROR:telegram.ext.dispatcher:No error handlers are registered, logging exception.
Traceback (most recent call last):
  File "/Library/Frameworks/Python.framework/Versions/3.9/lib/python3.9/site-packages/telegram/ext/dispatcher.py", line 555, in process_update
    handler.handle_update(update, self, check, context)
  File "/Library/Frameworks/Python.framework/Versions/3.9/lib/python3.9/site-packages/telegram/ext/conversationhandler.py", line 626, in handle_update
    new_state = handler.handle_update(update, dispatcher, check_result, context)
  File "/Library/Frameworks/Python.framework/Versions/3.9/lib/python3.9/site-packages/telegram/ext/handler.py", line 198, in handle_update
    return self.callback(update, context)
  File "/Users/anastasiyasundeeva/learnpython/2mybot/anketa.py", line 25, in anketa_name
    return rating
NameError: name 'rating' is not defined
INFO:telegram.ext.updater:Received signal 2 (SIGINT), stopping...
INFO:apscheduler.scheduler:Scheduler has been shut down
WARNING:telegram.ext.updater:Exiting immediately!
INFO:root:BOT starting... Date: Sat Mar 12 22:33:56 2022
INFO:apscheduler.scheduler:Scheduler started
ERROR:telegram.ext.dispatcher:No error handlers are registered, logging exception.
Traceback (most recent call last):
  File "/Library/Frameworks/Python.framework/Versions/3.9/lib/python3.9/site-packages/telegram/ext/dispatcher.py", line 555, in process_update
    handler.handle_update(update, self, check, context)
  File "/Library/Frameworks/Python.framework/Versions/3.9/lib/python3.9/site-packages/telegram/ext/conversationhandler.py", line 626, in handle_update
    new_state = handler.handle_update(update, dispatcher, check_result, context)
  File "/Library/Frameworks/Python.framework/Versions/3.9/lib/python3.9/site-packages/telegram/ext/handler.py", line 198, in handle_update
    return self.callback(update, context)
  File "/Users/anastasiyasundeeva/learnpython/2mybot/anketa.py", line 25, in anketa_name
    return rating
NameError: name 'rating' is not defined
INFO:telegram.ext.updater:Received signal 2 (SIGINT), stopping...
INFO:apscheduler.scheduler:Scheduler has been shut down
WARNING:telegram.ext.updater:Exiting immediately!
INFO:root:BOT starting... Date: Sat Mar 12 22:47:33 2022
INFO:apscheduler.scheduler:Scheduler started
ERROR:telegram.ext.dispatcher:No error handlers are registered, logging exception.
Traceback (most recent call last):
  File "/Library/Frameworks/Python.framework/Versions/3.9/lib/python3.9/site-packages/telegram/ext/dispatcher.py", line 555, in process_update
    handler.handle_update(update, self, check, context)
  File "/Library/Frameworks/Python.framework/Versions/3.9/lib/python3.9/site-packages/telegram/ext/conversationhandler.py", line 626, in handle_update
    new_state = handler.handle_update(update, dispatcher, check_result, context)
  File "/Library/Frameworks/Python.framework/Versions/3.9/lib/python3.9/site-packages/telegram/ext/handler.py", line 198, in handle_update
    return self.callback(update, context)
  File "/Users/anastasiyasundeeva/learnpython/2mybot/anketa.py", line 25, in anketa_name
    return rating
NameError: name 'rating' is not defined
INFO:telegram.ext.updater:Received signal 2 (SIGINT), stopping...
INFO:apscheduler.scheduler:Scheduler has been shut down
WARNING:telegram.ext.updater:Exiting immediately!
INFO:root:BOT starting... Date: Sat Mar 12 22:51:23 2022
INFO:apscheduler.scheduler:Scheduler started
ERROR:telegram.ext.dispatcher:No error handlers are registered, logging exception.
Traceback (most recent call last):
  File "/Library/Frameworks/Python.framework/Versions/3.9/lib/python3.9/site-packages/telegram/ext/dispatcher.py", line 555, in process_update
    handler.handle_update(update, self, check, context)
  File "/Library/Frameworks/Python.framework/Versions/3.9/lib/python3.9/site-packages/telegram/ext/conversationhandler.py", line 626, in handle_update
    new_state = handler.handle_update(update, dispatcher, check_result, context)
  File "/Library/Frameworks/Python.framework/Versions/3.9/lib/python3.9/site-packages/telegram/ext/handler.py", line 198, in handle_update
    return self.callback(update, context)
  File "/Users/anastasiyasundeeva/learnpython/2mybot/anketa.py", line 25, in anketa_name
    return rating
NameError: name 'rating' is not defined
ERROR:telegram.ext.dispatcher:No error handlers are registered, logging exception.
Traceback (most recent call last):
  File "/Library/Frameworks/Python.framework/Versions/3.9/lib/python3.9/site-packages/telegram/ext/dispatcher.py", line 555, in process_update
    handler.handle_update(update, self, check, context)
  File "/Library/Frameworks/Python.framework/Versions/3.9/lib/python3.9/site-packages/telegram/ext/conversationhandler.py", line 626, in handle_update
    new_state = handler.handle_update(update, dispatcher, check_result, context)
  File "/Library/Frameworks/Python.framework/Versions/3.9/lib/python3.9/site-packages/telegram/ext/handler.py", line 198, in handle_update
    return self.callback(update, context)
  File "/Users/anastasiyasundeeva/learnpython/2mybot/anketa.py", line 25, in anketa_name
    return rating
NameError: name 'rating' is not defined
INFO:telegram.ext.updater:Received signal 2 (SIGINT), stopping...
INFO:apscheduler.scheduler:Scheduler has been shut down
WARNING:telegram.ext.updater:Exiting immediately!
INFO:root:BOT starting... Date: Sat Mar 12 22:56:55 2022
INFO:apscheduler.scheduler:Scheduler started
ERROR:telegram.ext.dispatcher:No error handlers are registered, logging exception.
Traceback (most recent call last):
  File "/Library/Frameworks/Python.framework/Versions/3.9/lib/python3.9/site-packages/telegram/ext/dispatcher.py", line 555, in process_update
    handler.handle_update(update, self, check, context)
  File "/Library/Frameworks/Python.framework/Versions/3.9/lib/python3.9/site-packages/telegram/ext/conversationhandler.py", line 626, in handle_update
    new_state = handler.handle_update(update, dispatcher, check_result, context)
  File "/Library/Frameworks/Python.framework/Versions/3.9/lib/python3.9/site-packages/telegram/ext/handler.py", line 198, in handle_update
    return self.callback(update, context)
  File "/Users/anastasiyasundeeva/learnpython/2mybot/anketa.py", line 25, in anketa_name
    return rating
NameError: name 'rating' is not defined
INFO:telegram.ext.updater:Received signal 2 (SIGINT), stopping...
INFO:apscheduler.scheduler:Scheduler has been shut down
WARNING:telegram.ext.updater:Exiting immediately!
INFO:root:BOT starting... Date: Sat Mar 12 23:02:27 2022
INFO:apscheduler.scheduler:Scheduler started
ERROR:telegram.ext.dispatcher:No error handlers are registered, logging exception.
Traceback (most recent call last):
  File "/Library/Frameworks/Python.framework/Versions/3.9/lib/python3.9/site-packages/telegram/ext/dispatcher.py", line 555, in process_update
    handler.handle_update(update, self, check, context)
  File "/Library/Frameworks/Python.framework/Versions/3.9/lib/python3.9/site-packages/telegram/ext/conversationhandler.py", line 626, in handle_update
    new_state = handler.handle_update(update, dispatcher, check_result, context)
  File "/Library/Frameworks/Python.framework/Versions/3.9/lib/python3.9/site-packages/telegram/ext/handler.py", line 198, in handle_update
    return self.callback(update, context)
  File "/Users/anastasiyasundeeva/learnpython/2mybot/anketa.py", line 25, in anketa_name
    return rating
NameError: name 'rating' is not defined
INFO:root:BOT starting... Date: Sun Mar 13 16:37:26 2022
INFO:apscheduler.scheduler:Scheduler started
ERROR:telegram.ext.dispatcher:No error handlers are registered, logging exception.
Traceback (most recent call last):
  File "/Library/Frameworks/Python.framework/Versions/3.9/lib/python3.9/site-packages/telegram/ext/dispatcher.py", line 555, in process_update
    handler.handle_update(update, self, check, context)
  File "/Library/Frameworks/Python.framework/Versions/3.9/lib/python3.9/site-packages/telegram/ext/conversationhandler.py", line 626, in handle_update
    new_state = handler.handle_update(update, dispatcher, check_result, context)
  File "/Library/Frameworks/Python.framework/Versions/3.9/lib/python3.9/site-packages/telegram/ext/handler.py", line 198, in handle_update
    return self.callback(update, context)
  File "/Users/anastasiyasundeeva/learnpython/2mybot/anketa.py", line 26, in anketa_name
    return rating
NameError: name 'rating' is not defined
